<?xml version="1.0" ?>
<!-- =================================================================================== -->
<!-- |    This document was autogenerated by xacro from drone.urdf.xacro               | -->
<!-- |    EDITING THIS FILE BY HAND IS NOT RECOMMENDED                                 | -->
<!-- =================================================================================== -->
<robot name="drone">
  <link name="arm1">
    <visual>
      <origin rpy="0 1.5707963267948966 0" xyz="0.075 0 0"/>
      <geometry>
        <cylinder length="0.15" radius="0.01"/>
      </geometry>
      <material name="arm_material"/>
    </visual>
    <collision>
      <origin rpy="0 1.5707963267948966 0" xyz="0.075 0 0"/>
      <geometry>
        <cylinder length="0.15" radius="0.01"/>
      </geometry>
    </collision>
    <inertial>
      <mass value="0.02"/>
      <inertia ixx="3.75e-05" ixy="0.0" ixz="0.0" iyy="0.0" iyz="0.0" izz="3.75e-05"/>
    </inertial>
  </link>
  <joint name="frame_arm1" type="fixed">
    <parent link="frame"/>
    <child link="arm1"/>
    <origin rpy="0 0 -0.7853981633974483" xyz="0.2 -0.1 0"/>
  </joint>
  <link name="arm2">
    <visual>
      <origin rpy="0 1.5707963267948966 0" xyz="0.075 0 0"/>
      <geometry>
        <cylinder length="0.15" radius="0.01"/>
      </geometry>
      <material name="arm_material"/>
    </visual>
    <collision>
      <origin rpy="0 1.5707963267948966 0" xyz="0.075 0 0"/>
      <geometry>
        <cylinder length="0.15" radius="0.01"/>
      </geometry>
    </collision>
    <inertial>
      <mass value="0.02"/>
      <inertia ixx="3.75e-05" ixy="0.0" ixz="0.0" iyy="0.0" iyz="0.0" izz="3.75e-05"/>
    </inertial>
  </link>
  <joint name="frame_arm2" type="fixed">
    <parent link="frame"/>
    <child link="arm2"/>
    <origin rpy="0 0 0.7853981633974483" xyz="0.2 0.1 0"/>
  </joint>
  <link name="arm3">
    <visual>
      <origin rpy="0 1.5707963267948966 0" xyz="0.075 0 0"/>
      <geometry>
        <cylinder length="0.15" radius="0.01"/>
      </geometry>
      <material name="arm_material"/>
    </visual>
    <collision>
      <origin rpy="0 1.5707963267948966 0" xyz="0.075 0 0"/>
      <geometry>
        <cylinder length="0.15" radius="0.01"/>
      </geometry>
    </collision>
    <inertial>
      <mass value="0.02"/>
      <inertia ixx="3.75e-05" ixy="0.0" ixz="0.0" iyy="0.0" iyz="0.0" izz="3.75e-05"/>
    </inertial>
  </link>
  <joint name="frame_arm3" type="fixed">
    <parent link="frame"/>
    <child link="arm3"/>
    <origin rpy="0 0 2.356194490192345" xyz="-0.2 0.1 0"/>
  </joint>
  <link name="arm4">
    <visual>
      <origin rpy="0 1.5707963267948966 0" xyz="0.075 0 0"/>
      <geometry>
        <cylinder length="0.15" radius="0.01"/>
      </geometry>
      <material name="arm_material"/>
    </visual>
    <collision>
      <origin rpy="0 1.5707963267948966 0" xyz="0.075 0 0"/>
      <geometry>
        <cylinder length="0.15" radius="0.01"/>
      </geometry>
    </collision>
    <inertial>
      <mass value="0.02"/>
      <inertia ixx="3.75e-05" ixy="0.0" ixz="0.0" iyy="0.0" iyz="0.0" izz="3.75e-05"/>
    </inertial>
  </link>
  <joint name="frame_arm4" type="fixed">
    <parent link="frame"/>
    <child link="arm4"/>
    <origin rpy="0 0 -2.356194490192345" xyz="-0.2 -0.1 0"/>
  </joint>
  <link name="propeller1">
    <visual>
      <origin rpy="0 0 0" xyz="0 0 0"/>
      <geometry>
        <cylinder length="0.01" radius="0.1"/>
      </geometry>
      <material name="propeller_material"/>
    </visual>
    <collision>
      <origin rpy="0 0 0" xyz="0 0 0"/>
      <geometry>
        <cylinder length="0.01" radius="0.1"/>
      </geometry>
    </collision>
    <inertial>
      <mass value="0.02"/>
      <inertia ixx="5.016664660000001e-05" ixy="0.0" ixz="0.0" iyy="5.016664660000001e-05" iyz="0.0" izz="0.0001"/>
    </inertial>
  </link>
  <joint name="arm1_propeller1" type="continuous">
    <parent link="arm1"/>
    <child link="propeller1"/>
    <origin rpy="0 0 0.7853981633974483" xyz="0.15 0 0.024900000000000002"/>
    <axis xyz="0 0 1"/>
    <limit effort="0.1" velocity="10"/>
  </joint>
  <link name="propeller2">
    <visual>
      <origin rpy="0 0 0" xyz="0 0 0"/>
      <geometry>
        <cylinder length="0.01" radius="0.1"/>
      </geometry>
      <material name="propeller_material"/>
    </visual>
    <collision>
      <origin rpy="0 0 0" xyz="0 0 0"/>
      <geometry>
        <cylinder length="0.01" radius="0.1"/>
      </geometry>
    </collision>
    <inertial>
      <mass value="0.02"/>
      <inertia ixx="5.016664660000001e-05" ixy="0.0" ixz="0.0" iyy="5.016664660000001e-05" iyz="0.0" izz="0.0001"/>
    </inertial>
  </link>
  <joint name="arm2_propeller2" type="continuous">
    <parent link="arm2"/>
    <child link="propeller2"/>
    <origin rpy="0 0 0.7853981633974483" xyz="0.15 0 0.024900000000000002"/>
    <axis xyz="0 0 1"/>
    <limit effort="0.1" velocity="10"/>
  </joint>
  <link name="propeller3">
    <visual>
      <origin rpy="0 0 0" xyz="0 0 0"/>
      <geometry>
        <cylinder length="0.01" radius="0.1"/>
      </geometry>
      <material name="propeller_material"/>
    </visual>
    <collision>
      <origin rpy="0 0 0" xyz="0 0 0"/>
      <geometry>
        <cylinder length="0.01" radius="0.1"/>
      </geometry>
    </collision>
    <inertial>
      <mass value="0.02"/>
      <inertia ixx="5.016664660000001e-05" ixy="0.0" ixz="0.0" iyy="5.016664660000001e-05" iyz="0.0" izz="0.0001"/>
    </inertial>
  </link>
  <joint name="arm3_propeller3" type="continuous">
    <parent link="arm3"/>
    <child link="propeller3"/>
    <origin rpy="0 0 0.7853981633974483" xyz="0.15 0 0.024900000000000002"/>
    <axis xyz="0 0 1"/>
    <limit effort="0.1" velocity="10"/>
  </joint>
  <link name="propeller4">
    <visual>
      <origin rpy="0 0 0" xyz="0 0 0"/>
      <geometry>
        <cylinder length="0.01" radius="0.1"/>
      </geometry>
      <material name="propeller_material"/>
    </visual>
    <collision>
      <origin rpy="0 0 0" xyz="0 0 0"/>
      <geometry>
        <cylinder length="0.01" radius="0.1"/>
      </geometry>
    </collision>
    <inertial>
      <mass value="0.02"/>
      <inertia ixx="5.016664660000001e-05" ixy="0.0" ixz="0.0" iyy="5.016664660000001e-05" iyz="0.0" izz="0.0001"/>
    </inertial>
  </link>
  <joint name="arm4_propeller4" type="continuous">
    <parent link="arm4"/>
    <child link="propeller4"/>
    <origin rpy="0 0 0.7853981633974483" xyz="0.15 0 0.024900000000000002"/>
    <axis xyz="0 0 1"/>
    <limit effort="0.1" velocity="10"/>
  </joint>
  <!-- Frame -->
  <link name="frame">
    <visual>
      <origin rpy="0 0 0" xyz="0 0 0"/>
      <geometry>
        <box size="0.4 0.2 0.05"/>
      </geometry>
      <material name="frame_material"/>
    </visual>
    <collision>
      <origin rpy="0 0 0" xyz="0 0 0"/>
      <geometry>
        <box size="0.4 0.2 0.05"/>
      </geometry>
    </collision>
    <inertial>
      <mass value="0.88"/>
      <origin rpy="0 0 0" xyz="0 0 0"/>
      <inertia ixx="0.01191666666666667" ixy="0.0" ixz="0.0" iyy="0.0031166666666666673" iyz="0.0" izz="0.01466666666666667"/>
    </inertial>
  </link>
  <!-- materials -->
  <material name="frame_material">
    <color rgba="1 0.2 0.2 1"/>
  </material>
  <material name="arm_material">
    <color rgba="0.8 0.8 0.8 0.5"/>
  </material>
  <material name="propeller_material">
    <color rgba="0 0 0 0.5"/>
  </material>
</robot>
