<sdf version='1.9'>
  <world name='empty'>
    <physics name='1ms' type='ignored'>
      <max_step_size>0.001</max_step_size>
      <real_time_factor>1</real_time_factor>
      <real_time_update_rate>1000</real_time_update_rate>
    </physics>
    <plugin name='gz::sim::systems::Physics' filename='ignition-gazebo-physics-system'/>
    <plugin name='gz::sim::systems::UserCommands' filename='ignition-gazebo-user-commands-system'/>
    <plugin name='gz::sim::systems::SceneBroadcaster' filename='ignition-gazebo-scene-broadcaster-system'/>
    <plugin name='gz::sim::systems::Contact' filename='ignition-gazebo-contact-system'/>
    <gravity>0 0 -9.8</gravity>
    <magnetic_field>6e-06 2.3e-05 -4.2e-05</magnetic_field>
    <atmosphere type='adiabatic'/>
    <scene>
      <ambient>0.4 0.4 0.4 1</ambient>
      <background>0.7 0.7 0.7 1</background>
      <shadows>true</shadows>
    </scene>
    <model name='ground_plane'>
      <static>true</static>
      <link name='link'>
        <collision name='collision'>
          <geometry>
            <plane>
              <normal>0 0 1</normal>
              <size>100 100</size>
            </plane>
          </geometry>
          <surface>
            <friction>
              <ode/>
            </friction>
            <bounce/>
            <contact/>
          </surface>
        </collision>
        <visual name='visual'>
          <geometry>
            <plane>
              <normal>0 0 1</normal>
              <size>100 100</size>
            </plane>
          </geometry>
          <material>
            <ambient>0.8 0.8 0.8 1</ambient>
            <diffuse>0.8 0.8 0.8 1</diffuse>
            <specular>0.8 0.8 0.8 1</specular>
          </material>
        </visual>
        <pose>0 0 0 0 -0 0</pose>
        <inertial>
          <pose>0 0 0 0 -0 0</pose>
          <mass>1</mass>
          <inertia>
            <ixx>1</ixx>
            <ixy>0</ixy>
            <ixz>0</ixz>
            <iyy>1</iyy>
            <iyz>0</iyz>
            <izz>1</izz>
          </inertia>
        </inertial>
        <enable_wind>false</enable_wind>
      </link>
      <pose>0 0 0 0 -0 0</pose>
      <self_collide>false</self_collide>
    </model>
    <model name='drone_model'>
      <link name='frame'>
        <inertial>
          <pose>0 0 0 0 -0 0</pose>
          <mass>0.95999999999999996</mass>
          <inertia>
            <ixx>0.0127917</ixx>
            <ixy>0</ixy>
            <ixz>0</ixz>
            <iyy>0.0063916700000000003</iyy>
            <iyz>0</iyz>
            <izz>0.018816699999999999</izz>
          </inertia>
        </inertial>
        <collision name='frame_collision'>
          <pose>0 0 0 0 0 0</pose>
          <geometry>
            <box>
              <size>0.4 0.2 0.05</size>
            </box>
          </geometry>
          <surface>
            <friction>
              <ode/>
            </friction>
            <bounce/>
            <contact/>
          </surface>
        </collision>
        <collision name='frame_fixed_joint_lump__arm1_collision_1'>
          <pose>0.2530330085889911 -0.1530330085889911 0 0 1.570796326794897 -0.7853981633974483</pose>
          <geometry>
            <cylinder>
              <length>0.14999999999999999</length>
              <radius>0.01</radius>
            </cylinder>
          </geometry>
          <surface>
            <friction>
              <ode/>
            </friction>
            <bounce/>
            <contact/>
          </surface>
        </collision>
        <collision name='frame_fixed_joint_lump__arm2_collision_2'>
          <pose>0.2530330085889911 0.1530330085889911 0 0 1.570796326794897 0.7853981633974483</pose>
          <geometry>
            <cylinder>
              <length>0.14999999999999999</length>
              <radius>0.01</radius>
            </cylinder>
          </geometry>
          <surface>
            <friction>
              <ode/>
            </friction>
            <bounce/>
            <contact/>
          </surface>
        </collision>
        <collision name='frame_fixed_joint_lump__arm3_collision_3'>
          <pose>-0.2530330085889911 0.1530330085889911 0 0 1.570796326794897 2.356194490192345</pose>
          <geometry>
            <cylinder>
              <length>0.14999999999999999</length>
              <radius>0.01</radius>
            </cylinder>
          </geometry>
          <surface>
            <friction>
              <ode/>
            </friction>
            <bounce/>
            <contact/>
          </surface>
        </collision>
        <collision name='frame_fixed_joint_lump__arm4_collision_4'>
          <pose>-0.2530330085889911 -0.1530330085889911 0 0 1.570796326794897 -2.356194490192345</pose>
          <geometry>
            <cylinder>
              <length>0.14999999999999999</length>
              <radius>0.01</radius>
            </cylinder>
          </geometry>
          <surface>
            <friction>
              <ode/>
            </friction>
            <bounce/>
            <contact/>
          </surface>
        </collision>
        <visual name='frame_visual'>
          <pose>0 0 0 0 0 0</pose>
          <geometry>
            <box>
              <size>0.4 0.2 0.05</size>
            </box>
          </geometry>
          <material>
            <diffuse>1 0.25 0.25 1</diffuse>
            <ambient>1 0.25 0.25 1</ambient>
          </material>
        </visual>
        <visual name='frame_fixed_joint_lump__arm1_visual_1'>
          <pose>0.2530330085889911 -0.1530330085889911 0 0 1.570796326794897 -0.7853981633974483</pose>
          <geometry>
            <cylinder>
              <length>0.14999999999999999</length>
              <radius>0.01</radius>
            </cylinder>
          </geometry>
          <material>
            <diffuse>1 1 1 0.5</diffuse>
            <ambient>1 1 1 0.5</ambient>
          </material>
        </visual>
        <visual name='frame_fixed_joint_lump__arm2_visual_2'>
          <pose>0.2530330085889911 0.1530330085889911 0 0 1.570796326794897 0.7853981633974483</pose>
          <geometry>
            <cylinder>
              <length>0.14999999999999999</length>
              <radius>0.01</radius>
            </cylinder>
          </geometry>
          <material>
            <diffuse>1 1 1 0.5</diffuse>
            <ambient>1 1 1 0.5</ambient>
          </material>
        </visual>
        <visual name='frame_fixed_joint_lump__arm3_visual_3'>
          <pose>-0.2530330085889911 0.1530330085889911 0 0 1.570796326794897 2.356194490192345</pose>
          <geometry>
            <cylinder>
              <length>0.14999999999999999</length>
              <radius>0.01</radius>
            </cylinder>
          </geometry>
          <material>
            <diffuse>1 1 1 0.5</diffuse>
            <ambient>1 1 1 0.5</ambient>
          </material>
        </visual>
        <visual name='frame_fixed_joint_lump__arm4_visual_4'>
          <pose>-0.2530330085889911 -0.1530330085889911 0 0 1.570796326794897 -2.356194490192345</pose>
          <geometry>
            <cylinder>
              <length>0.14999999999999999</length>
              <radius>0.01</radius>
            </cylinder>
          </geometry>
          <material>
            <diffuse>1 1 1 0.5</diffuse>
            <ambient>1 1 1 0.5</ambient>
          </material>
        </visual>
        <pose>0 0 0 0 -0 0</pose>
        <enable_wind>false</enable_wind>
      </link>
      <joint name='arm1_propeller1' type='revolute'>
        <pose>0 0 0 0 -0 0</pose>
        <parent>frame</parent>
        <child>propeller1</child>
        <axis>
          <xyz>0 0 1</xyz>
          <limit>
            <lower>-10000000000000000</lower>
            <upper>10000000000000000</upper>
            <effort>0.10000000000000001</effort>
            <velocity>10</velocity>
            <stiffness>100000000</stiffness>
            <dissipation>1</dissipation>
          </limit>
          <dynamics>
            <spring_reference>0</spring_reference>
            <spring_stiffness>0</spring_stiffness>
            <damping>0</damping>
            <friction>0</friction>
          </dynamics>
        </axis>
      </joint>
      <link name='propeller1'>
        <pose>0.306066 -0.206066 0.0249 0 0 -0</pose>
        <inertial>
          <pose>0 0 0 0 -0 0</pose>
          <mass>0.02</mass>
          <inertia>
            <ixx>5.0166600000000002e-05</ixx>
            <ixy>0</ixy>
            <ixz>0</ixz>
            <iyy>5.0166600000000002e-05</iyy>
            <iyz>0</iyz>
            <izz>0.0001</izz>
          </inertia>
        </inertial>
        <collision name='propeller1_collision'>
          <pose>0 0 0 0 0 0</pose>
          <geometry>
            <cylinder>
              <length>0.01</length>
              <radius>0.10000000000000001</radius>
            </cylinder>
          </geometry>
          <surface>
            <friction>
              <ode/>
            </friction>
            <bounce/>
            <contact/>
          </surface>
        </collision>
        <visual name='propeller1_visual'>
          <pose>0 0 0 0 0 0</pose>
          <geometry>
            <cylinder>
              <length>0.01</length>
              <radius>0.10000000000000001</radius>
            </cylinder>
          </geometry>
          <material>
            <diffuse>0 0 0 0.5</diffuse>
            <ambient>0 0 0 0.5</ambient>
          </material>
        </visual>
        <enable_wind>false</enable_wind>
      </link>
      <joint name='arm2_propeller2' type='revolute'>
        <pose>-0 0 0 0 -0 0</pose>
        <parent>frame</parent>
        <child>propeller2</child>
        <axis>
          <xyz>0 0 1</xyz>
          <limit>
            <lower>-10000000000000000</lower>
            <upper>10000000000000000</upper>
            <effort>0.10000000000000001</effort>
            <velocity>10</velocity>
            <stiffness>100000000</stiffness>
            <dissipation>1</dissipation>
          </limit>
          <dynamics>
            <spring_reference>0</spring_reference>
            <spring_stiffness>0</spring_stiffness>
            <damping>0</damping>
            <friction>0</friction>
          </dynamics>
        </axis>
      </joint>
      <link name='propeller2'>
        <pose>0.306066 0.206066 0.0249 0 0 1.57085</pose>
        <inertial>
          <pose>0 0 0 0 -0 0</pose>
          <mass>0.02</mass>
          <inertia>
            <ixx>5.0166600000000002e-05</ixx>
            <ixy>0</ixy>
            <ixz>0</ixz>
            <iyy>5.0166600000000002e-05</iyy>
            <iyz>0</iyz>
            <izz>0.0001</izz>
          </inertia>
        </inertial>
        <collision name='propeller2_collision'>
          <pose>0 0 0 0 0 0</pose>
          <geometry>
            <cylinder>
              <length>0.01</length>
              <radius>0.10000000000000001</radius>
            </cylinder>
          </geometry>
          <surface>
            <friction>
              <ode/>
            </friction>
            <bounce/>
            <contact/>
          </surface>
        </collision>
        <visual name='propeller2_visual'>
          <pose>0 0 0 0 0 0</pose>
          <geometry>
            <cylinder>
              <length>0.01</length>
              <radius>0.10000000000000001</radius>
            </cylinder>
          </geometry>
          <material>
            <diffuse>0 0 0 0.5</diffuse>
            <ambient>0 0 0 0.5</ambient>
          </material>
        </visual>
        <enable_wind>false</enable_wind>
      </link>
      <joint name='arm3_propeller3' type='revolute'>
        <pose>0 0 0 0 -0 0</pose>
        <parent>frame</parent>
        <child>propeller3</child>
        <axis>
          <xyz>0 0 1</xyz>
          <limit>
            <lower>-10000000000000000</lower>
            <upper>10000000000000000</upper>
            <effort>0.10000000000000001</effort>
            <velocity>10</velocity>
            <stiffness>100000000</stiffness>
            <dissipation>1</dissipation>
          </limit>
          <dynamics>
            <spring_reference>0</spring_reference>
            <spring_stiffness>0</spring_stiffness>
            <damping>0</damping>
            <friction>0</friction>
          </dynamics>
        </axis>
      </joint>
      <link name='propeller3'>
        <pose>-0.306066 0.206066 0.0249 0 0 3.14154</pose>
        <inertial>
          <pose>0 0 0 0 -0 0</pose>
          <mass>0.02</mass>
          <inertia>
            <ixx>5.0166600000000002e-05</ixx>
            <ixy>0</ixy>
            <ixz>0</ixz>
            <iyy>5.0166600000000002e-05</iyy>
            <iyz>0</iyz>
            <izz>0.0001</izz>
          </inertia>
        </inertial>
        <collision name='propeller3_collision'>
          <pose>0 0 0 0 0 0</pose>
          <geometry>
            <cylinder>
              <length>0.01</length>
              <radius>0.10000000000000001</radius>
            </cylinder>
          </geometry>
          <surface>
            <friction>
              <ode/>
            </friction>
            <bounce/>
            <contact/>
          </surface>
        </collision>
        <visual name='propeller3_visual'>
          <pose>0 0 0 0 0 0</pose>
          <geometry>
            <cylinder>
              <length>0.01</length>
              <radius>0.10000000000000001</radius>
            </cylinder>
          </geometry>
          <material>
            <diffuse>0 0 0 0.5</diffuse>
            <ambient>0 0 0 0.5</ambient>
          </material>
        </visual>
        <enable_wind>false</enable_wind>
      </link>
      <joint name='arm4_propeller4' type='revolute'>
        <pose>0 0 0 0 -0 0</pose>
        <parent>frame</parent>
        <child>propeller4</child>
        <axis>
          <xyz>0 0 1</xyz>
          <limit>
            <lower>-10000000000000000</lower>
            <upper>10000000000000000</upper>
            <effort>0.10000000000000001</effort>
            <velocity>10</velocity>
            <stiffness>100000000</stiffness>
            <dissipation>1</dissipation>
          </limit>
          <dynamics>
            <spring_reference>0</spring_reference>
            <spring_stiffness>0</spring_stiffness>
            <damping>0</damping>
            <friction>0</friction>
          </dynamics>
        </axis>
      </joint>
      <link name='propeller4'>
        <pose>-0.306066 -0.206066 0.0249 0 0 -1.5708</pose>
        <inertial>
          <pose>0 0 0 0 -0 0</pose>
          <mass>0.02</mass>
          <inertia>
            <ixx>5.0166600000000002e-05</ixx>
            <ixy>0</ixy>
            <ixz>0</ixz>
            <iyy>5.0166600000000002e-05</iyy>
            <iyz>0</iyz>
            <izz>0.0001</izz>
          </inertia>
        </inertial>
        <collision name='propeller4_collision'>
          <pose>0 0 0 0 0 0</pose>
          <geometry>
            <cylinder>
              <length>0.01</length>
              <radius>0.10000000000000001</radius>
            </cylinder>
          </geometry>
          <surface>
            <friction>
              <ode/>
            </friction>
            <bounce/>
            <contact/>
          </surface>
        </collision>
        <visual name='propeller4_visual'>
          <pose>0 0 0 0 0 0</pose>
          <geometry>
            <cylinder>
              <length>0.01</length>
              <radius>0.10000000000000001</radius>
            </cylinder>
          </geometry>
          <material>
            <diffuse>0 0 0 0.5</diffuse>
            <ambient>0 0 0 0.5</ambient>
          </material>
        </visual>
        <enable_wind>false</enable_wind>
      </link>
      <frame name='frame_arm1' attached_to='frame'>
        <pose>0.2 -0.1 0 0 0 -0.785398</pose>
      </frame>
      <frame name='arm1' attached_to='frame_arm1'/>
      <frame name='frame_arm2' attached_to='frame'>
        <pose>0.2 0.1 0 0 -0 0.785398</pose>
      </frame>
      <frame name='arm2' attached_to='frame_arm2'/>
      <frame name='frame_arm3' attached_to='frame'>
        <pose>-0.2 0.1 0 0 -0 2.35619</pose>
      </frame>
      <frame name='arm3' attached_to='frame_arm3'/>
      <frame name='frame_arm4' attached_to='frame'>
        <pose>-0.2 -0.1 0 0 0 -2.35619</pose>
      </frame>
      <frame name='arm4' attached_to='frame_arm4'/>
      <pose>0 -0.146245 0.025 0 0 -0</pose>
      <static>false</static>
      <self_collide>false</self_collide>
    </model>
    <light name='sun' type='directional'>
      <pose>0 0 10 0 -0 0</pose>
      <cast_shadows>true</cast_shadows>
      <intensity>1</intensity>
      <direction>-0.5 0.1 -0.9</direction>
      <diffuse>0.8 0.8 0.8 1</diffuse>
      <specular>0.2 0.2 0.2 1</specular>
      <attenuation>
        <range>1000</range>
        <linear>0.01</linear>
        <constant>0.90000000000000002</constant>
        <quadratic>0.001</quadratic>
      </attenuation>
      <spot>
        <inner_angle>0</inner_angle>
        <outer_angle>0</outer_angle>
        <falloff>0</falloff>
      </spot>
    </light>
  </world>
</sdf>
